<?xml version="1.0"?>
<!-- This URDF was automatically created by SolidWorks to URDF Exporter! Originally created by Stephen Brawner (brawner@gmail.com) 
     Commit Version: 1.6.0-1-g15f4949  Build Version: 1.6.7594.29634
     For more information, please see http://wiki.ros.org/sw_urdf_exporter -->
<robot xmlns:xacro="http://www.ros.org/wiki/xacro" name="rml_63">
  <xacro:property name="M_PI" value="3.14159265358"/>

  <!-- Transmissions for ROS Control -->
  <xacro:macro name="transmission_block" params="joint_name">
    <transmission name="tran_${joint_name}">
      <type>transmission_interface/SimpleTransmission</type>
      <joint name="${joint_name}">
        <hardwareInterface>hardware_interface/PositionJointInterface</hardwareInterface>
      </joint>
      <actuator name="motor_${joint_name}">
        <hardwareInterface>hardware_interface/PositionJointInterface</hardwareInterface>
        <mechanicalReduction>1</mechanicalReduction>
      </actuator>
    </transmission>
  </xacro:macro>

  <xacro:macro name="rml_63" params="prefix:=left">
    <link
      name="rml_link_${prefix}">
      <inertial>
        <origin
          xyz="0.0014231 -0.00010178 0.050147"
          rpy="0 0 0" />
        <mass
          value="0.66171" />
        <inertia
          ixx="0.00099443"
          ixy="3.282E-06"
          ixz="-9.9964E-06"
          iyy="0.0010144"
          iyz="1.2811E-06"
          izz="0.00067929" />
      </inertial>
      <visual>
        <origin
          xyz="0 0 0"
          rpy="0 0 0" />
        <geometry>
          <mesh filename="package://smartcar_description/urdf/xacro/rm_description/meshes/RML63/base_link.STL" />
          <!-- <mesh filename="package://smartcar_description/urdf/stl/dz_prt.stl" /> -->
        </geometry>
        <material
          name="">
          <color
            rgba="1 1 1 1" />
        </material>
      </visual>
      <collision>
        <origin
          xyz="0 0 0"
          rpy="0 0 0" />
        <geometry>
          <mesh filename="package://smartcar_description/urdf/xacro/rm_description/meshes/RML63/base_link.STL" />
          <!-- <mesh filename="package://smartcar_description/urdf/stl/dz_prt.stl" /> -->
        </geometry>
      </collision>
    </link>
    <link
      name="link1_${prefix}">
      <inertial>
        <origin
          xyz="-0.043281 -0.0072256 -0.012694"
          rpy="0 0 0" />
        <mass
          value="0.89496" />
        <inertia
          ixx="0.0010156"
          ixy="-0.00026764"
          ixz="0.00045014"
          iyy="0.0024107"
          iyz="6.0996E-05"
          izz="0.0022755" />
      </inertial>
      <visual>
        <origin
          xyz="0 0 0"
          rpy="0 0 0" />
        <geometry>
          <mesh filename="package://smartcar_description/urdf/xacro/rm_description/meshes/RML63/link1.STL" />
          <!-- <mesh filename="package://smartcar_description/urdf/stl/dz-1_prt.stl" /> -->
        </geometry>
        <material
          name="">
          <color
            rgba="1 1 1 1" />
        </material>
      </visual>
      <collision>
        <origin
          xyz="0 0 0"
          rpy="0 0 0" />
        <geometry> 
          <mesh filename="package://smartcar_description/urdf/xacro/rm_description/meshes/RML63/link1.STL" />
          <!-- <mesh filename="package://smartcar_description/urdf/stl/dz-1_prt.stl" /> -->
        </geometry>
      </collision>
    </link>
    <joint
      name="joint1_${prefix}"
      type="revolute">
      <origin
        xyz="0 0 0.172"
        rpy="0 0 0" />
      <parent
        link="rml_link_${prefix}" />
      <child
        link="link1_${prefix}" />
      <axis
        xyz="0 0 1" />
      <limit
        lower="-3.106"
        upper="3.106"
        effort="100"
        velocity="1" />
    </joint>
    <link
      name="link2_${prefix}">
      <inertial>
        <origin
          xyz="0.17388 3.639E-07 -0.089966"
          rpy="0 0 0" />
        <mass
          value="1.5679" />
        <inertia
          ixx="0.0010615"
          ixy="-7.3371E-08"
          ixz="-0.00025488"
          iyy="0.03035"
          iyz="-1.6148E-08"
          izz="0.030485" />
      </inertial>
      <visual>
        <origin
          xyz="0 0 0"
          rpy="0 0 0" />
        <geometry>
          <mesh filename="package://smartcar_description/urdf/xacro/rm_description/meshes/RML63/link2.STL" />
          <!-- <mesh filename="package://smartcar_description/urdf/stl/link1_prt.stl" /> -->
        </geometry>
        <material
          name="">
          <color
            rgba="1 1 1 1" />
        </material>
      </visual>
      <collision>
        <origin
          xyz="0 0 0"
          rpy="0 0 0" />
        <geometry>
          <mesh filename="package://smartcar_description/urdf/xacro/rm_description/meshes/RML63/link2.STL" />
          <!-- <mesh filename="package://smartcar_description/urdf/stl/link1_prt.stl" /> -->
        </geometry>
      </collision>
    </link>
    <joint
      name="joint2_${prefix}"
      type="revolute">
      <origin
        xyz="-0.086 0 0"
        rpy="0 -1.5708 -1.5708" />
      <parent
        link="link1_${prefix}" />
      <child
        link="link2_${prefix}" />
      <axis
        xyz="0 0 1" />
      <limit
        lower="-3.106"
        upper="3.106"
        effort="100"
        velocity="1" />
    </joint>
    <link
      name="link3_${prefix}">
      <inertial>
        <origin
          xyz="0.035968 -0.020568 -0.0048526"
          rpy="0 0 0" />
        <mass
          value="0.67539" />
        <inertia
          ixx="0.00091144"
          ixy="0.00043238"
          ixz="-0.0001205"
          iyy="0.0012128"
          iyz="6.6376E-05"
          izz="0.0015231" />
      </inertial>
      <visual>
        <origin
          xyz="0 0 0"
          rpy="0 0 0" />
        <geometry>
          <mesh filename="package://smartcar_description/urdf/xacro/rm_description/meshes/RML63/link3.STL" />
          <!-- <mesh filename="package://smartcar_description/urdf/stl/link2_prt.stl" /> -->
        </geometry>
        <material
          name="">
          <color
            rgba="1 1 1 1" />
        </material>
      </visual>
      <collision>
        <origin
          xyz="0 0 0"
          rpy="0 0 0" />
        <geometry>
          <mesh filename="package://smartcar_description/urdf/xacro/rm_description/meshes/RML63/link3.STL" />
          <!-- <mesh filename="package://smartcar_description/urdf/stl/link2_prt.stl" /> -->
        </geometry>
      </collision>
    </link>
    <joint
      name="joint3_${prefix}"
      type="revolute">
      <origin
        xyz="0.38 0 -0.00030011"
        rpy="0 0 1.5708" />
      <parent
        link="link2_${prefix}" />
      <child
        link="link3_${prefix}" />
      <axis
        xyz="0 0 1" />
      <limit
        lower="-3.106"
        upper="2.53"
        effort="100"
        velocity="1" />
    </joint>
    <link
      name="link4_${prefix}">
      <inertial>
        <origin
          xyz="-2.0098E-06 -0.033559 -0.18296"
          rpy="0 0 0" />
        <mass
          value="0.69687" />
        <inertia
          ixx="0.0085449"
          ixy="4.7796E-08"
          ixz="-1.0943E-08"
          iyy="0.0080043"
          iyz="0.0020032"
          izz="0.00084216" />
      </inertial>
      <visual>
        <origin
          xyz="0 0 0"
          rpy="0 0 0" />
        <geometry>
          <mesh filename="package://smartcar_description/urdf/xacro/rm_description/meshes/RML63/link4.STL" />
          <!-- <mesh filename="package://smartcar_description/urdf/stl/link3_prt.stl" /> -->
        </geometry>
        <material
          name="">
          <color
            rgba="1 1 1 1" />
        </material>
      </visual>
      <collision>
        <origin
          xyz="0 0 0"
          rpy="0 0 0" />
        <geometry>
          <mesh filename="package://smartcar_description/urdf/xacro/rm_description/meshes/RML63/link4.STL" />
          <!-- <mesh filename="package://smartcar_description/urdf/stl/link3_prt.stl" /> -->
        </geometry>
      </collision>
    </link>
    <joint
      name="joint4_${prefix}"
      type="revolute">
      <origin
        xyz="0.069 -0.405 0.00029958"
        rpy="1.5708 0 0" />
      <parent
        link="link3_${prefix}" />
      <child
        link="link4_${prefix}" />
      <axis
        xyz="0 0 1" />
      <limit
        lower="-3.106"
        upper="3.106"
        effort="100"
        velocity="1" />
    </joint>
    <link
      name="link5_${prefix}">
      <inertial>
        <origin
          xyz="-1.5679E-07 0.02862 -0.0062118"
          rpy="0 0 0" />
        <mass
          value="0.34759" />
        <inertia
          ixx="0.00049457"
          ixy="-1.0235E-08"
          ixz="-1.8949E-09"
          iyy="0.00019706"
          iyz="-6.3439E-05"
          izz="0.00044565" />
      </inertial>
      <visual>
        <origin
          xyz="0 0 0"
          rpy="0 0 0" />
        <geometry>
          <mesh filename="package://smartcar_description/urdf/xacro//rm_description/meshes/RML63/link5.STL" />
          <!-- <mesh filename="package://smartcar_description/urdf/stl/link4_prt.stl" /> -->
        </geometry>
        <material
          name="">
          <color
            rgba="1 1 1 1" />
        </material>
      </visual>
      <collision>
        <origin
          xyz="0 0 0"
          rpy="0 0 0" />
        <geometry>
          <mesh filename="package://smartcar_description/urdf/xacro//rm_description/meshes/RML63/link5.STL" />
          <!-- <mesh filename="package://smartcar_description/urdf/stl/link4_prt.stl" /> -->
        </geometry>
      </collision>
    </link>
    <joint
      name="joint5_${prefix}"
      type="revolute">
      <origin
        xyz="0 0 0"
        rpy="1.5708 0 3.1416" />
      <parent
        link="link4_${prefix}" />
      <child
        link="link5_${prefix}" />
      <axis
        xyz="0 0 1" />
      <limit
        lower="-3.106"
        upper="3.106"
        effort="100"
        velocity="1" />
    </joint>
    <link
      name="link6_${prefix}">
      <inertial>
        <origin
          xyz="-0.0006163 0.00034085 -0.01449"
          rpy="0 0 0" />
        <mass
          value="0.077104" />
        <inertia
          ixx="2.2947E-05"
          ixy="-1.3061E-06"
          ixz="1.1202E-07"
          iyy="2.1475E-05"
          iyz="-5.1151E-08"
          izz="3.4243E-05" />
      </inertial>
      <visual>
        <origin
          xyz="0 0 0"
          rpy="0 0 0" />
        <geometry>
          <mesh filename="package://smartcar_description/urdf/xacro//rm_description/meshes/RML63/link6.STL" />
          <!-- <mesh filename="package://smartcar_description/urdf/stl/link5_prt.stl" /> -->
        </geometry>
        <material
          name="">
          <color
            rgba="1 1 1 1" />
        </material>
      </visual>
      <collision>
        <origin
          xyz="0 0 0"
          rpy="0 0 0" />
        <geometry>
          <mesh filename="package://smartcar_description/urdf/xacro//rm_description/meshes/RML63/link6.STL" />
          <!-- <mesh filename="package://smartcar_description/urdf/stl/link5_prt.stl" /> -->
        </geometry>
      </collision>
    </link>
    <joint
      name="joint6_${prefix}"
      type="revolute">
      <origin
        xyz="0 0.115 0"
        rpy="1.5708 0 3.1416" />
      <parent
        link="link5_${prefix}" />
      <child
        link="link6_${prefix}" />
      <axis
        xyz="0 0 1" />
      <limit
        lower="-6.28"
        upper="6.28"
        effort="100"
        velocity="1" />
    </joint>

    <xacro:transmission_block joint_name="joint1_${prefix}"/>
    <xacro:transmission_block joint_name="joint2_${prefix}"/>
    <xacro:transmission_block joint_name="joint3_${prefix}"/>
    <xacro:transmission_block joint_name="joint4_${prefix}"/>
    <xacro:transmission_block joint_name="joint5_${prefix}"/>
    <xacro:transmission_block joint_name="joint6_${prefix}"/>

  </xacro:macro>
</robot>
